[2021-12-29 14:27:03,945] {taskinstance.py:876} INFO - Dependencies all met for <TaskInstance: trigger_rule.task1 2021-12-28T00:00:00+00:00 [queued]>
[2021-12-29 14:27:04,011] {taskinstance.py:876} INFO - Dependencies all met for <TaskInstance: trigger_rule.task1 2021-12-28T00:00:00+00:00 [queued]>
[2021-12-29 14:27:04,011] {taskinstance.py:1067} INFO - 
--------------------------------------------------------------------------------
[2021-12-29 14:27:04,012] {taskinstance.py:1068} INFO - Starting attempt 1 of 1
[2021-12-29 14:27:04,014] {taskinstance.py:1069} INFO - 
--------------------------------------------------------------------------------
[2021-12-29 14:27:04,039] {taskinstance.py:1087} INFO - Executing <Task(BashOperator): task1> on 2021-12-28T00:00:00+00:00
[2021-12-29 14:27:04,041] {standard_task_runner.py:52} INFO - Started process 11231 to run task
[2021-12-29 14:27:04,086] {standard_task_runner.py:76} INFO - Running: ['airflow', 'tasks', 'run', 'trigger_rule', 'task1', '2021-12-28T00:00:00+00:00', '--job-id', '45', '--pool', 'default_pool', '--raw', '--subdir', 'DAGS_FOLDER/trigger_rule.py', '--cfg-path', '/tmp/tmpd0dwg2p8', '--error-file', '/tmp/tmp7gu3whnr']
[2021-12-29 14:27:04,111] {standard_task_runner.py:77} INFO - Job 45: Subtask task1
[2021-12-29 14:27:04,513] {logging_mixin.py:104} INFO - Running <TaskInstance: trigger_rule.task1 2021-12-28T00:00:00+00:00 [running]> on host airflowvm
[2021-12-29 14:27:04,767] {taskinstance.py:1280} INFO - Exporting the following env vars:
AIRFLOW_CTX_DAG_OWNER=airflow
AIRFLOW_CTX_DAG_ID=trigger_rule
AIRFLOW_CTX_TASK_ID=task1
AIRFLOW_CTX_EXECUTION_DATE=2021-12-28T00:00:00+00:00
AIRFLOW_CTX_DAG_RUN_ID=scheduled__2021-12-28T00:00:00+00:00
[2021-12-29 14:27:04,768] {subprocess.py:52} INFO - Tmp dir root location: 
 /tmp
[2021-12-29 14:27:04,770] {subprocess.py:63} INFO - Running command: ['bash', '-c', 'exit 1']
[2021-12-29 14:27:04,778] {subprocess.py:75} INFO - Output:
[2021-12-29 14:27:04,781] {subprocess.py:83} INFO - Command exited with return code 1
[2021-12-29 14:27:04,795] {taskinstance.py:1481} ERROR - Task failed with exception
Traceback (most recent call last):
  File "/home/airflow/airflow-course/venv/lib/python3.8/site-packages/airflow/models/taskinstance.py", line 1137, in _run_raw_task
    self._prepare_and_execute_task_with_callbacks(context, task)
  File "/home/airflow/airflow-course/venv/lib/python3.8/site-packages/airflow/models/taskinstance.py", line 1311, in _prepare_and_execute_task_with_callbacks
    result = self._execute_task(context, task_copy)
  File "/home/airflow/airflow-course/venv/lib/python3.8/site-packages/airflow/models/taskinstance.py", line 1341, in _execute_task
    result = task_copy.execute(context=context)
  File "/home/airflow/airflow-course/venv/lib/python3.8/site-packages/airflow/operators/bash.py", line 180, in execute
    raise AirflowException('Bash command failed. The command returned a non-zero exit code.')
airflow.exceptions.AirflowException: Bash command failed. The command returned a non-zero exit code.
[2021-12-29 14:27:04,800] {taskinstance.py:1524} INFO - Marking task as FAILED. dag_id=trigger_rule, task_id=task1, execution_date=20211228T000000, start_date=20211229T142703, end_date=20211229T142704
[2021-12-29 14:27:04,848] {local_task_job.py:151} INFO - Task exited with return code 1
