[2021-12-28 18:49:07,560] {taskinstance.py:876} INFO - Dependencies all met for <TaskInstance: xcom_dag.choose_best_model 2021-12-28T18:48:26.022580+00:00 [queued]>
[2021-12-28 18:49:07,569] {taskinstance.py:876} INFO - Dependencies all met for <TaskInstance: xcom_dag.choose_best_model 2021-12-28T18:48:26.022580+00:00 [queued]>
[2021-12-28 18:49:07,569] {taskinstance.py:1067} INFO - 
--------------------------------------------------------------------------------
[2021-12-28 18:49:07,569] {taskinstance.py:1068} INFO - Starting attempt 1 of 1
[2021-12-28 18:49:07,569] {taskinstance.py:1069} INFO - 
--------------------------------------------------------------------------------
[2021-12-28 18:49:07,584] {taskinstance.py:1087} INFO - Executing <Task(PythonOperator): choose_best_model> on 2021-12-28T18:48:26.022580+00:00
[2021-12-28 18:49:07,585] {standard_task_runner.py:52} INFO - Started process 13227 to run task
[2021-12-28 18:49:07,593] {standard_task_runner.py:76} INFO - Running: ['airflow', 'tasks', 'run', 'xcom_dag', 'choose_best_model', '2021-12-28T18:48:26.022580+00:00', '--job-id', '31', '--pool', 'default_pool', '--raw', '--subdir', 'DAGS_FOLDER/xcom_dag.py', '--cfg-path', '/tmp/tmpnpmhejug', '--error-file', '/tmp/tmp1y5h4b7k']
[2021-12-28 18:49:07,594] {standard_task_runner.py:77} INFO - Job 31: Subtask choose_best_model
[2021-12-28 18:49:07,748] {logging_mixin.py:104} INFO - Running <TaskInstance: xcom_dag.choose_best_model 2021-12-28T18:48:26.022580+00:00 [running]> on host airflowvm
[2021-12-28 18:49:07,862] {taskinstance.py:1280} INFO - Exporting the following env vars:
AIRFLOW_CTX_DAG_OWNER=airflow
AIRFLOW_CTX_DAG_ID=xcom_dag
AIRFLOW_CTX_TASK_ID=choose_best_model
AIRFLOW_CTX_EXECUTION_DATE=2021-12-28T18:48:26.022580+00:00
AIRFLOW_CTX_DAG_RUN_ID=manual__2021-12-28T18:48:26.022580+00:00
[2021-12-28 18:49:07,862] {logging_mixin.py:104} INFO - choose best model
[2021-12-28 18:49:07,863] {taskinstance.py:1481} ERROR - Task failed with exception
Traceback (most recent call last):
  File "/home/airflow/airflow-course/venv/lib/python3.8/site-packages/airflow/models/taskinstance.py", line 1137, in _run_raw_task
    self._prepare_and_execute_task_with_callbacks(context, task)
  File "/home/airflow/airflow-course/venv/lib/python3.8/site-packages/airflow/models/taskinstance.py", line 1311, in _prepare_and_execute_task_with_callbacks
    result = self._execute_task(context, task_copy)
  File "/home/airflow/airflow-course/venv/lib/python3.8/site-packages/airflow/models/taskinstance.py", line 1341, in _execute_task
    result = task_copy.execute(context=context)
  File "/home/airflow/airflow-course/venv/lib/python3.8/site-packages/airflow/operators/python.py", line 150, in execute
    return_value = self.execute_callable()
  File "/home/airflow/airflow-course/venv/lib/python3.8/site-packages/airflow/operators/python.py", line 161, in execute_callable
    return self.python_callable(*self.op_args, **self.op_kwargs)
  File "/home/airflow/airflow/dags/xcom_dag.py", line 22, in _choose_best_model
    key=model_accuracy,
NameError: name 'model_accuracy' is not defined
[2021-12-28 18:49:07,873] {taskinstance.py:1524} INFO - Marking task as FAILED. dag_id=xcom_dag, task_id=choose_best_model, execution_date=20211228T184826, start_date=20211228T184907, end_date=20211228T184907
[2021-12-28 18:49:07,929] {local_task_job.py:151} INFO - Task exited with return code 1
